Workbook
Name UPDATE: 'Data Sheet'!$E$1

Sheet Financials>

Sheet HistoricalFS
B2: ="Historical Financial Statement - "&'Data Sheet'!B1 -> Historical Financial Statement - HINDUSTAN UNILEVER LTD
B3: Years | C3: ='Data Sheet'!B16 -> 42825 | D3: ='Data Sheet'!C16 -> 43190 | E3: ='Data Sheet'!D16 -> 43555 | F3: ='Data Sheet'!E16 -> 43921 | G3: ='Data Sheet'!F16 -> 44286 | H3: ='Data Sheet'!G16 -> 44651 | I3: ='Data Sheet'!H16 -> 45016 | J3: ='Data Sheet'!I16 -> 45382 | K3: ='Data Sheet'!J16 -> 45747
A5: # | B5: Income Statement
B6: Sales | C6: =IFERROR('Data Sheet'!B17,0) -> 33162 | D6: =IFERROR('Data Sheet'!C17,0) -> 35545 | E6: =IFERROR('Data Sheet'!D17,0) -> 39310 | F6: =IFERROR('Data Sheet'!E17,0) -> 39783 | G6: =IFERROR('Data Sheet'!F17,0) -> 47028 | H6: =IFERROR('Data Sheet'!G17,0) -> 52446 | I6: =IFERROR('Data Sheet'!H17,0) -> 60580 | J6: =IFERROR('Data Sheet'!I17,0) -> 61896 | K6: =IFERROR('Data Sheet'!J17,0) -> 63121
B7: Sales Growth | C7: - | D7: =D6/C6-1 -> 0.071859357 | E7: =E6/D6-1 -> 0.10592207 | F7: =F6/E6-1 -> 0.012032562 | G7: =G6/F6-1 -> 0.18211296 | H7: =H6/G6-1 -> 0.11520796 | I7: =I6/H6-1 -> 0.15509286 | J7: =J6/I6-1 -> 0.021723341 | K7: =K6/J6-1 -> 0.019791263
B9: COGS | C9: =IFERROR(SUM('Data Sheet'!B18,'Data Sheet'!B20:B22)-1*'Data Sheet'!B19,"-") -> 18675 | D9: =IFERROR(SUM('Data Sheet'!C18,'Data Sheet'!C20:C22)-1*'Data Sheet'!C19,"-") -> 19314 | E9: =IFERROR(SUM('Data Sheet'!D18,'Data Sheet'!D20:D22)-1*'Data Sheet'!D19,"-") -> 21081 | F9: =IFERROR(SUM('Data Sheet'!E18,'Data Sheet'!E20:E22)-1*'Data Sheet'!E19,"-") -> 20614 | G9: =IFERROR(SUM('Data Sheet'!F18,'Data Sheet'!F20:F22)-1*'Data Sheet'!F19,"-") -> 25301 | H9: =IFERROR(SUM('Data Sheet'!G18,'Data Sheet'!G20:G22)-1*'Data Sheet'!G19,"-") -> 29066 | I9: =IFERROR(SUM('Data Sheet'!H18,'Data Sheet'!H20:H22)-1*'Data Sheet'!H19,"-") -> 35381 | J9: =IFERROR(SUM('Data Sheet'!I18,'Data Sheet'!I20:I22)-1*'Data Sheet'!I19,"-") -> 33651 | K9: =IFERROR(SUM('Data Sheet'!J18,'Data Sheet'!J20:J22)-1*'Data Sheet'!J19,"-") -> 34529
B10: COGS as % Sales | C10: =C9/C6 -> 0.56314456 | D10: =D9/D6 -> 0.54336756 | E10: =E9/E6 -> 0.53627576 | F10: =F9/F6 -> 0.51816102 | G10: =G9/G6 -> 0.53799864 | H10: =H9/H6 -> 0.55420814 | I10: =I9/I6 -> 0.58403764 | J10: =J9/J6 -> 0.54367003 | K10: =K9/K6 -> 0.54702872
B12: Gross Profit | C12: =C6-C9 -> 14487 | D12: =D6-D9 -> 16231 | E12: =E6-E9 -> 18229 | F12: =F6-F9 -> 19169 | G12: =G6-G9 -> 21727 | H12: =H6-H9 -> 23380 | I12: =I6-I9 -> 25199 | J12: =J6-J9 -> 28245 | K12: =K6-K9 -> 28592
B13: Gross Margin | C13: =C12/C6 -> 0.43685544 | D13: =D12/D6 -> 0.45663244 | E13: =E12/E6 -> 0.46372424 | F13: =F12/F6 -> 0.48183898 | G13: =G12/G6 -> 0.46200136 | H13: =H12/H6 -> 0.44579186 | I13: =I12/I6 -> 0.41596236 | J13: =J12/J6 -> 0.45632997 | K13: =K12/K6 -> 0.45297128
B15: Selling & General Expenses | C15: =IFERROR(SUM('Data Sheet'!B23:B24),0) -> 8159 | D15: =IFERROR(SUM('Data Sheet'!C23:C24),0) -> 8732 | E15: =IFERROR(SUM('Data Sheet'!D23:D24),0) -> 9349 | F15: =IFERROR(SUM('Data Sheet'!E23:E24),0) -> 9308 | G15: =IFERROR(SUM('Data Sheet'!F23:F24),0) -> 10101 | H15: =IFERROR(SUM('Data Sheet'!G23:G24),0) -> 10523 | I15: =IFERROR(SUM('Data Sheet'!H23:H24),0) -> 11052 | J15: =IFERROR(SUM('Data Sheet'!I23:I24),0) -> 13586 | K15: =IFERROR(SUM('Data Sheet'!J23:J24),0) -> 13749
B16: S&G as % Sales | C16: =C15/C9 -> 0.43689424 | D16: =D15/D9 -> 0.45210728 | E16: =E15/E9 -> 0.44347991 | F16: =F15/F9 -> 0.45153779 | G16: =G15/G9 -> 0.39923323 | H16: =H15/H9 -> 0.36203812 | I16: =I15/I9 -> 0.31237105 | J16: =J15/J9 -> 0.40373243 | K16: =K15/K9 -> 0.39818703
B18: EBITDA | C18: =C12-C15 -> 6328 | D18: =D12-D15 -> 7499 | E18: =E12-E15 -> 8880 | F18: =F12-F15 -> 9861 | G18: =G12-G15 -> 11626 | H18: =H12-H15 -> 12857 | I18: =I12-I15 -> 14147 | J18: =J12-J15 -> 14659 | K18: =K12-K15 -> 14843
B19: EBITDA as % Sales | C19: =C18/C6 -> 0.19082082 | D19: =D18/D6 -> 0.21097201 | E19: =E18/E6 -> 0.22589672 | F19: =F18/F6 -> 0.24786969 | G19: =G18/G6 -> 0.24721443 | H19: =H18/H6 -> 0.24514739 | I19: =I18/I6 -> 0.23352592 | J19: =J18/J6 -> 0.23683275 | K19: =K18/K6 -> 0.23515153
B21: Depreciation | C21: =IFERROR('Data Sheet'!B26,0) -> 432 | D21: =IFERROR('Data Sheet'!C26,0) -> 520 | E21: =IFERROR('Data Sheet'!D26,0) -> 565 | F21: =IFERROR('Data Sheet'!E26,0) -> 1002 | G21: =IFERROR('Data Sheet'!F26,0) -> 1074 | H21: =IFERROR('Data Sheet'!G26,0) -> 1091 | I21: =IFERROR('Data Sheet'!H26,0) -> 1137 | J21: =IFERROR('Data Sheet'!I26,0) -> 1216 | K21: =IFERROR('Data Sheet'!J26,0) -> 1355
B22: Depreciation as % Sales | C22: =C21/C6 -> 0.013026959 | D22: =D21/D6 -> 0.014629343 | E22: =E21/E6 -> 0.014372933 | F22: =F21/F6 -> 0.025186638 | G22: =G21/G6 -> 0.022837459 | H22: =H21/H6 -> 0.020802349 | I22: =I21/I6 -> 0.01876857 | J22: =J21/J6 -> 0.019645858 | K22: =K21/K6 -> 0.021466707
B24: EBIT | C24: =C18-C21 -> 5896 | D24: =D18-D21 -> 6979 | E24: =E18-E21 -> 8315 | F24: =F18-F21 -> 8859 | G24: =G18-G21 -> 10552 | H24: =H18-H21 -> 11766 | I24: =I18-I21 -> 13010 | J24: =J18-J21 -> 13443 | K24: =K18-K21 -> 13488
B25: EBITDA as % Sales | C25: =C24/C6 -> 0.17779386 | D25: =D24/D6 -> 0.19634266 | E25: =E24/E6 -> 0.21152379 | F25: =F24/F6 -> 0.22268306 | G25: =G24/G6 -> 0.22437697 | H25: =H24/H6 -> 0.22434504 | I25: =I24/I6 -> 0.21475735 | J25: =J24/J6 -> 0.21718689 | K25: =K24/K6 -> 0.21368483
B27: Interest | C27: =IFERROR('Data Sheet'!B27,0) -> 35 | D27: =IFERROR('Data Sheet'!C27,0) -> 26 | E27: =IFERROR('Data Sheet'!D27,0) -> 33 | F27: =IFERROR('Data Sheet'!E27,0) -> 118 | G27: =IFERROR('Data Sheet'!F27,0) -> 117 | H27: =IFERROR('Data Sheet'!G27,0) -> 106 | I27: =IFERROR('Data Sheet'!H27,0) -> 114 | J27: =IFERROR('Data Sheet'!I27,0) -> 334 | K27: =IFERROR('Data Sheet'!J27,0) -> 395
B28: Interest as % Sales | C28: =C27/C6 -> 0.0010554249 | D28: =D27/D6 -> 0.00073146715 | E28: =E27/E6 -> 0.00083948105 | F28: =F27/F6 -> 0.002966091 | G28: =G27/G6 -> 0.0024878796 | H28: =H27/H6 -> 0.0020211265 | I28: =I27/I6 -> 0.0018818092 | J28: =J27/J6 -> 0.0053961484 | K28: =K27/K6 -> 0.0062578223
B30: EBT | C30: =C24-C27 -> 5861 | D30: =D24-D27 -> 6953 | E30: =E24-E27 -> 8282 | F30: =F24-F27 -> 8741 | G30: =G24-G27 -> 10435 | H30: =H24-H27 -> 11660 | I30: =I24-I27 -> 12896 | J30: =J24-J27 -> 13109 | K30: =K24-K27 -> 13093
B31: EBT as % Sales | C31: =C30/C6 -> 0.17673844 | D31: =D30/D6 -> 0.1956112 | E31: =E30/E6 -> 0.2106843 | F31: =F30/F6 -> 0.21971696 | G31: =G30/G6 -> 0.22188909 | H31: =H30/H6 -> 0.22232391 | I31: =I30/I6 -> 0.21287554 | J31: =J30/J6 -> 0.21179075 | K31: =K30/K6 -> 0.20742701
B33: Tax | C33: =IFERROR('Data Sheet'!B29,0) -> 1977 | D33: =IFERROR('Data Sheet'!C29,0) -> 2079 | E33: =IFERROR('Data Sheet'!D29,0) -> 2544 | F33: =IFERROR('Data Sheet'!E29,0) -> 2409 | G33: =IFERROR('Data Sheet'!F29,0) -> 2606 | H33: =IFERROR('Data Sheet'!G29,0) -> 2987 | I33: =IFERROR('Data Sheet'!H29,0) -> 3201 | J33: =IFERROR('Data Sheet'!I29,0) -> 3644 | K33: =IFERROR('Data Sheet'!J29,0) -> 3744
B34: Effective Tax Rate | C34: =C33/C30 -> 0.33731445 | D34: =D33/D30 -> 0.29900762 | E34: =E33/E30 -> 0.30717218 | F34: =F33/F30 -> 0.27559776 | G34: =G33/G30 -> 0.24973646 | H34: =H33/H30 -> 0.25617496 | I34: =I33/I30 -> 0.2482165 | J34: =J33/J30 -> 0.27797696 | K34: =K33/K30 -> 0.28595433
B36: Net Profit | C36: =C30-C33 -> 3884 | D36: =D30-D33 -> 4874 | E36: =E30-E33 -> 5738 | F36: =F30-F33 -> 6332 | G36: =G30-G33 -> 7829 | H36: =H30-H33 -> 8673 | I36: =I30-I33 -> 9695 | J36: =J30-J33 -> 9465 | K36: =K30-K33 -> 9349
B37: Net Margins | C37: =C36/C6 -> 0.11712201 | D37: =D36/D6 -> 0.13712196 | E37: =E36/E6 -> 0.14596795 | F37: =F36/F6 -> 0.15916346 | G37: =G36/G6 -> 0.16647529 | H37: =H36/H6 -> 0.16537009 | I37: =I36/I6 -> 0.16003632 | J37: =J36/J6 -> 0.1529178 | K37: =K36/K6 -> 0.14811236
B39: No of Equity Shares | C39: =IFERROR('Data Sheet'!B93,0) -> 216.43 | D39: =IFERROR('Data Sheet'!C93,0) -> 216.45 | E39: =IFERROR('Data Sheet'!D93,0) -> 216.47 | F39: =IFERROR('Data Sheet'!E93,0) -> 216.48 | G39: =IFERROR('Data Sheet'!F93,0) -> 234.96 | H39: =IFERROR('Data Sheet'!G93,0) -> 234.96 | I39: =IFERROR('Data Sheet'!H93,0) -> 234.96 | J39: =IFERROR('Data Sheet'!I93,0) -> 234.96 | K39: =IFERROR('Data Sheet'!J93,0) -> 234.96
B41: Earnings Per Share | C41: =IFERROR(C36/C39,0) -> 17.945756 | D41: =IFERROR(D36/D39,0) -> 22.517903 | E41: =IFERROR(E36/E39,0) -> 26.507137 | F41: =IFERROR(F36/F39,0) -> 29.249815 | G41: =IFERROR(G36/G39,0) -> 33.320565 | H41: =IFERROR(H36/H39,0) -> 36.912666 | I41: =IFERROR(I36/I39,0) -> 41.262343 | J41: =IFERROR(J36/J39,0) -> 40.283453 | K41: =IFERROR(K36/K39,0) -> 39.789751
B42: Earnings Per Share Growth | C42: - | D42: =D41/C41-1 -> 0.25477591 | E42: =E41/D41-1 -> 0.17715836 | F42: =F41/E41-1 -> 0.10346941 | G42: =G41/F41-1 -> 0.13917182 | H42: =H41/G41-1 -> 0.10780432 | I42: =I41/H41-1 -> 0.11783697 | J42: =J41/I41-1 -> -0.023723569 | K42: =K41/J41-1 -> -0.012255679
B44: Dividends Per Share | C44: =IFERROR('Data Sheet'!B31/'Data Sheet'!B93,0) -> 16.966225 | D44: =IFERROR('Data Sheet'!C31/'Data Sheet'!C93,0) -> 19.95842 | E44: =IFERROR('Data Sheet'!D31/'Data Sheet'!D93,0) -> 21.952234 | F44: =IFERROR('Data Sheet'!E31/'Data Sheet'!E93,0) -> 24.944568 | G44: =IFERROR('Data Sheet'!F31/'Data Sheet'!F93,0) -> 40.506895 | H44: =IFERROR('Data Sheet'!G31/'Data Sheet'!G93,0) -> 34.005788 | I44: =IFERROR('Data Sheet'!H31/'Data Sheet'!H93,0) -> 39.006639 | J44: =IFERROR('Data Sheet'!I31/'Data Sheet'!I93,0) -> 42.00715 | K44: =IFERROR('Data Sheet'!J31/'Data Sheet'!J93,0) -> 53.009023
B45: Dividends Payout Ratio | C45: =C44/C41 -> 0.9454171 | D45: =D44/D41 -> 0.88633566 | E45: =E44/E41 -> 0.82816312 | F45: =F44/F41 -> 0.85281112 | G45: =G44/G41 -> 1.2156725 | H45: =H44/H41 -> 0.92124986 | I45: =I44/I41 -> 0.94533265 | J45: =J44/J41 -> 1.0427892 | K45: =K44/K41 -> 1.332228
B47: Retained Earnings | C47: =IFERROR(IF(C41>C44,1-C45,0),0) -> 0.054582904 | D47: =IFERROR(IF(D41>D44,1-D45,0),0) -> 0.11366434 | E47: =IFERROR(IF(E41>E44,1-E45,0),0) -> 0.17183688 | F47: =IFERROR(IF(F41>F44,1-F45,0),0) -> 0.14718888 | G47: =IFERROR(IF(G41>G44,1-G45,0),0) -> 0 | H47: =IFERROR(IF(H41>H44,1-H45,0),0) -> 0.078750144 | I47: =IFERROR(IF(I41>I44,1-I45,0),0) -> 0.054667354 | J47: =IFERROR(IF(J41>J44,1-J45,0),0) -> 0 | K47: =IFERROR(IF(K41>K44,1-K45,0),0) -> 0
A49: # | B49: Balance Sheet
B50: Equity Share Capital | C50: =IFERROR('Data Sheet'!B57,0) -> 216 | D50: =IFERROR('Data Sheet'!C57,0) -> 216 | E50: =IFERROR('Data Sheet'!D57,0) -> 216 | F50: =IFERROR('Data Sheet'!E57,0) -> 216 | G50: =IFERROR('Data Sheet'!F57,0) -> 235 | H50: =IFERROR('Data Sheet'!G57,0) -> 235 | I50: =IFERROR('Data Sheet'!H57,0) -> 235 | J50: =IFERROR('Data Sheet'!I57,0) -> 235 | K50: =IFERROR('Data Sheet'!J57,0) -> 235
B51: Reserves | C51: =IFERROR('Data Sheet'!B58,0) -> 6528 | D51: =IFERROR('Data Sheet'!C58,0) -> 7065 | E51: =IFERROR('Data Sheet'!D58,0) -> 7651 | F51: =IFERROR('Data Sheet'!E58,0) -> 8013 | G51: =IFERROR('Data Sheet'!F58,0) -> 47439 | H51: =IFERROR('Data Sheet'!G58,0) -> 48826 | I51: =IFERROR('Data Sheet'!H58,0) -> 50069 | J51: =IFERROR('Data Sheet'!I58,0) -> 50983 | K51: =IFERROR('Data Sheet'!J58,0) -> 49167
B52: Borrowings | C52: =IFERROR('Data Sheet'!B59,0) -> 277 | D52: =IFERROR('Data Sheet'!C59,0) -> 0 | E52: =IFERROR('Data Sheet'!D59,0) -> 99 | F52: =IFERROR('Data Sheet'!E59,0) -> 0 | G52: =IFERROR('Data Sheet'!F59,0) -> 0 | H52: =IFERROR('Data Sheet'!G59,0) -> 1043 | I52: =IFERROR('Data Sheet'!H59,0) -> 1219 | J52: =IFERROR('Data Sheet'!I59,0) -> 1484 | K52: =IFERROR('Data Sheet'!J59,0) -> 1648
B53: Other Liabilities | C53: =IFERROR('Data Sheet'!B60,0) -> 8685 | D53: =IFERROR('Data Sheet'!C60,0) -> 10581 | E53: =IFERROR('Data Sheet'!D60,0) -> 10663 | F53: =IFERROR('Data Sheet'!E60,0) -> 11924 | G53: =IFERROR('Data Sheet'!F60,0) -> 21066 | H53: =IFERROR('Data Sheet'!G60,0) -> 20402 | I53: =IFERROR('Data Sheet'!H60,0) -> 21554 | J53: =IFERROR('Data Sheet'!I60,0) -> 25787 | K53: =IFERROR('Data Sheet'!J60,0) -> 28813
B54: Total Liabilities | C54: =IFERROR('Data Sheet'!B61,0) -> 15706 | D54: =IFERROR('Data Sheet'!C61,0) -> 17862 | E54: =IFERROR('Data Sheet'!D61,0) -> 18629 | F54: =IFERROR('Data Sheet'!E61,0) -> 20153 | G54: =IFERROR('Data Sheet'!F61,0) -> 68740 | H54: =IFERROR('Data Sheet'!G61,0) -> 70506 | I54: =IFERROR('Data Sheet'!H61,0) -> 73077 | J54: =IFERROR('Data Sheet'!I61,0) -> 78489 | K54: =IFERROR('Data Sheet'!J61,0) -> 79863
B56: Fixed Assets Net Block | C56: =IFERROR('Data Sheet'!B62,0) -> 4419 | D56: =IFERROR('Data Sheet'!C62,0) -> 4528 | E56: =IFERROR('Data Sheet'!D62,0) -> 4715 | F56: =IFERROR('Data Sheet'!E62,0) -> 5479 | G56: =IFERROR('Data Sheet'!F62,0) -> 51443 | H56: =IFERROR('Data Sheet'!G62,0) -> 51473 | I56: =IFERROR('Data Sheet'!H62,0) -> 52678 | J56: =IFERROR('Data Sheet'!I62,0) -> 53744 | K56: =IFERROR('Data Sheet'!J62,0) -> 54335
B57: Capital Work in Progress | C57: =IFERROR('Data Sheet'!B63,0) -> 229 | D57: =IFERROR('Data Sheet'!C63,0) -> 461 | E57: =IFERROR('Data Sheet'!D63,0) -> 406 | F57: =IFERROR('Data Sheet'!E63,0) -> 597 | G57: =IFERROR('Data Sheet'!F63,0) -> 745 | H57: =IFERROR('Data Sheet'!G63,0) -> 1313 | I57: =IFERROR('Data Sheet'!H63,0) -> 1132 | J57: =IFERROR('Data Sheet'!I63,0) -> 1025 | K57: =IFERROR('Data Sheet'!J63,0) -> 1009
B58: Investments | C58: =IFERROR('Data Sheet'!B64,0) -> 3794 | D58: =IFERROR('Data Sheet'!C64,0) -> 2873 | E58: =IFERROR('Data Sheet'!D64,0) -> 2716 | F58: =IFERROR('Data Sheet'!E64,0) -> 1255 | G58: =IFERROR('Data Sheet'!F64,0) -> 2709 | H58: =IFERROR('Data Sheet'!G64,0) -> 3521 | I58: =IFERROR('Data Sheet'!H64,0) -> 2882 | J58: =IFERROR('Data Sheet'!I64,0) -> 4625 | K58: =IFERROR('Data Sheet'!J64,0) -> 3810
...

Sheet Common Size Statement
B2: ="Common Size Statement - "&'Data Sheet'!B1 -> Common Size Statement - HINDUSTAN UNILEVER LTD
B3: Years | C3: ='Data Sheet'!B16 -> 42825 | D3: ='Data Sheet'!C16 -> 43190 | E3: ='Data Sheet'!D16 -> 43555 | F3: ='Data Sheet'!E16 -> 43921 | G3: ='Data Sheet'!F16 -> 44286 | H3: ='Data Sheet'!G16 -> 44651 | I3: ='Data Sheet'!H16 -> 45016 | J3: ='Data Sheet'!I16 -> 45382 | K3: ='Data Sheet'!J16 -> 45747 | L3: ='Data Sheet'!#REF! -> #REF! | M3: LTM
A5: # | B5: Income Statement
B6: Sales | C6: =IFERROR(HistoricalFS!C6/HistoricalFS!C6,0) -> 1 | D6: =IFERROR(HistoricalFS!D6/HistoricalFS!D6,0) -> 1 | E6: =IFERROR(HistoricalFS!E6/HistoricalFS!E6,0) -> 1 | F6: =IFERROR(HistoricalFS!F6/HistoricalFS!F6,0) -> 1 | G6: =IFERROR(HistoricalFS!G6/HistoricalFS!G6,0) -> 1 | H6: =IFERROR(HistoricalFS!H6/HistoricalFS!H6,0) -> 1 | I6: =IFERROR(HistoricalFS!I6/HistoricalFS!I6,0) -> 1 | J6: =IFERROR(HistoricalFS!J6/HistoricalFS!J6,0) -> 1 | K6: =IFERROR(HistoricalFS!K6/HistoricalFS!K6,0) -> 1 | L6: =IFERROR(HistoricalFS!#REF!/HistoricalFS!#REF!,0) -> 0 | M6: =IFERROR(HistoricalFS!#REF!/HistoricalFS!#REF!,0) -> 0
B7: COGS | C7: =IFERROR(HistoricalFS!C10,0) -> 0.56314456 | D7: =IFERROR(HistoricalFS!D10,0) -> 0.54336756 | E7: =IFERROR(HistoricalFS!E10,0) -> 0.53627576 | F7: =IFERROR(HistoricalFS!F10,0) -> 0.51816102 | G7: =IFERROR(HistoricalFS!G10,0) -> 0.53799864 | H7: =IFERROR(HistoricalFS!H10,0) -> 0.55420814 | I7: =IFERROR(HistoricalFS!I10,0) -> 0.58403764 | J7: =IFERROR(HistoricalFS!J10,0) -> 0.54367003 | K7: =IFERROR(HistoricalFS!K10,0) -> 0.54702872 | L7: =IFERROR(HistoricalFS!#REF!,0) -> 0 | M7: =IFERROR(HistoricalFS!#REF!,0) -> 0
B8: Gross Profit | C8: =IFERROR(HistoricalFS!C12/HistoricalFS!C6,0) -> 0.43685544 | D8: =IFERROR(HistoricalFS!D12/HistoricalFS!D6,0) -> 0.45663244 | E8: =IFERROR(HistoricalFS!E12/HistoricalFS!E6,0) -> 0.46372424 | F8: =IFERROR(HistoricalFS!F12/HistoricalFS!F6,0) -> 0.48183898 | G8: =IFERROR(HistoricalFS!G12/HistoricalFS!G6,0) -> 0.46200136 | H8: =IFERROR(HistoricalFS!H12/HistoricalFS!H6,0) -> 0.44579186 | I8: =IFERROR(HistoricalFS!I12/HistoricalFS!I6,0) -> 0.41596236 | J8: =IFERROR(HistoricalFS!J12/HistoricalFS!J6,0) -> 0.45632997 | K8: =IFERROR(HistoricalFS!K12/HistoricalFS!K6,0) -> 0.45297128 | L8: =IFERROR(HistoricalFS!#REF!/HistoricalFS!#REF!,0) -> 0 | M8: =IFERROR(HistoricalFS!#REF!/HistoricalFS!#REF!,0) -> 0
B9: Selling &General Expense | C9: =IFERROR(HistoricalFS!C16,0) -> 0.43689424 | D9: =IFERROR(HistoricalFS!D16,0) -> 0.45210728 | E9: =IFERROR(HistoricalFS!E16,0) -> 0.44347991 | F9: =IFERROR(HistoricalFS!F16,0) -> 0.45153779 | G9: =IFERROR(HistoricalFS!G16,0) -> 0.39923323 | H9: =IFERROR(HistoricalFS!H16,0) -> 0.36203812 | I9: =IFERROR(HistoricalFS!I16,0) -> 0.31237105 | J9: =IFERROR(HistoricalFS!J16,0) -> 0.40373243 | K9: =IFERROR(HistoricalFS!K16,0) -> 0.39818703 | L9: =IFERROR(HistoricalFS!#REF!,0) -> 0 | M9: =IFERROR(HistoricalFS!#REF!,0) -> 0
B10: EBITDA | C10: =IFERROR(HistoricalFS!C19,0) -> 0.19082082 | D10: =IFERROR(HistoricalFS!D19,0) -> 0.21097201 | E10: =IFERROR(HistoricalFS!E19,0) -> 0.22589672 | F10: =IFERROR(HistoricalFS!F19,0) -> 0.24786969 | G10: =IFERROR(HistoricalFS!G19,0) -> 0.24721443 | H10: =IFERROR(HistoricalFS!H19,0) -> 0.24514739 | I10: =IFERROR(HistoricalFS!I19,0) -> 0.23352592 | J10: =IFERROR(HistoricalFS!J19,0) -> 0.23683275 | K10: =IFERROR(HistoricalFS!K19,0) -> 0.23515153 | L10: =IFERROR(HistoricalFS!#REF!,0) -> 0 | M10: =IFERROR(HistoricalFS!#REF!,0) -> 0
B11: Depreciation & Amortisation | C11: =IFERROR(HistoricalFS!C22,0) -> 0.013026959 | D11: =IFERROR(HistoricalFS!D22,0) -> 0.014629343 | E11: =IFERROR(HistoricalFS!E22,0) -> 0.014372933 | F11: =IFERROR(HistoricalFS!F22,0) -> 0.025186638 | G11: =IFERROR(HistoricalFS!G22,0) -> 0.022837459 | H11: =IFERROR(HistoricalFS!H22,0) -> 0.020802349 | I11: =IFERROR(HistoricalFS!I22,0) -> 0.01876857 | J11: =IFERROR(HistoricalFS!J22,0) -> 0.019645858 | K11: =IFERROR(HistoricalFS!K22,0) -> 0.021466707 | L11: =IFERROR(HistoricalFS!#REF!,0) -> 0 | M11: =IFERROR(HistoricalFS!#REF!,0) -> 0
B12: EBIT | C12: =IFERROR((HistoricalFS!C30+HistoricalFS!C27)/HistoricalFS!C6,0) -> 0.17779386 | D12: =IFERROR((HistoricalFS!D30+HistoricalFS!D27)/HistoricalFS!D6,0) -> 0.19634266 | E12: =IFERROR((HistoricalFS!E30+HistoricalFS!E27)/HistoricalFS!E6,0) -> 0.21152379 | F12: =IFERROR((HistoricalFS!F30+HistoricalFS!F27)/HistoricalFS!F6,0) -> 0.22268306 | G12: =IFERROR((HistoricalFS!G30+HistoricalFS!G27)/HistoricalFS!G6,0) -> 0.22437697 | H12: =IFERROR((HistoricalFS!H30+HistoricalFS!H27)/HistoricalFS!H6,0) -> 0.22434504 | I12: =IFERROR((HistoricalFS!I30+HistoricalFS!I27)/HistoricalFS!I6,0) -> 0.21475735 | J12: =IFERROR((HistoricalFS!J30+HistoricalFS!J27)/HistoricalFS!J6,0) -> 0.21718689 | K12: =IFERROR((HistoricalFS!K30+HistoricalFS!K27)/HistoricalFS!K6,0) -> 0.21368483 | L12: =IFERROR((HistoricalFS!#REF!+HistoricalFS!#REF!)/HistoricalFS!#REF!,0) -> 0 | M12: =IFERROR((HistoricalFS!#REF!+HistoricalFS!#REF!)/HistoricalFS!#REF!,0) -> 0
B13: Interest | C13: =IFERROR(HistoricalFS!C28,0) -> 0.0010554249 | D13: =IFERROR(HistoricalFS!D28,0) -> 0.00073146715 | E13: =IFERROR(HistoricalFS!E28,0) -> 0.00083948105 | F13: =IFERROR(HistoricalFS!F28,0) -> 0.002966091 | G13: =IFERROR(HistoricalFS!G28,0) -> 0.0024878796 | H13: =IFERROR(HistoricalFS!H28,0) -> 0.0020211265 | I13: =IFERROR(HistoricalFS!I28,0) -> 0.0018818092 | J13: =IFERROR(HistoricalFS!J28,0) -> 0.0053961484 | K13: =IFERROR(HistoricalFS!K28,0) -> 0.0062578223 | L13: =IFERROR(HistoricalFS!#REF!,0) -> 0 | M13: =IFERROR(HistoricalFS!#REF!,0) -> 0
B14: EBT | C14: =IFERROR(HistoricalFS!C31,0) -> 0.17673844 | D14: =IFERROR(HistoricalFS!D31,0) -> 0.1956112 | E14: =IFERROR(HistoricalFS!E31,0) -> 0.2106843 | F14: =IFERROR(HistoricalFS!F31,0) -> 0.21971696 | G14: =IFERROR(HistoricalFS!G31,0) -> 0.22188909 | H14: =IFERROR(HistoricalFS!H31,0) -> 0.22232391 | I14: =IFERROR(HistoricalFS!I31,0) -> 0.21287554 | J14: =IFERROR(HistoricalFS!J31,0) -> 0.21179075 | K14: =IFERROR(HistoricalFS!K31,0) -> 0.20742701 | L14: =IFERROR(HistoricalFS!#REF!,0) -> 0 | M14: =IFERROR(HistoricalFS!#REF!,0) -> 0
B15: Tax | C15: =IFERROR(HistoricalFS!C33/HistoricalFS!C9,0) -> 0.10586345 | D15: =IFERROR(HistoricalFS!D33/HistoricalFS!D9,0) -> 0.10764212 | E15: =IFERROR(HistoricalFS!E33/HistoricalFS!E9,0) -> 0.12067739 | F15: =IFERROR(HistoricalFS!F33/HistoricalFS!F9,0) -> 0.11686233 | G15: =IFERROR(HistoricalFS!G33/HistoricalFS!G9,0) -> 0.10299988 | H15: =IFERROR(HistoricalFS!H33/HistoricalFS!H9,0) -> 0.10276612 | I15: =IFERROR(HistoricalFS!I33/HistoricalFS!I9,0) -> 0.090472287 | J15: =IFERROR(HistoricalFS!J33/HistoricalFS!J9,0) -> 0.10828802 | K15: =IFERROR(HistoricalFS!K33/HistoricalFS!K9,0) -> 0.10843059 | L15: =IFERROR(HistoricalFS!#REF!/HistoricalFS!#REF!,0) -> 0 | M15: =IFERROR(HistoricalFS!#REF!/HistoricalFS!#REF!,0) -> 0
B16: Net Profit | C16: =IFERROR(HistoricalFS!C36/HistoricalFS!C6,0) -> 0.11712201 | D16: =IFERROR(HistoricalFS!D36/HistoricalFS!D6,0) -> 0.13712196 | E16: =IFERROR(HistoricalFS!E36/HistoricalFS!E6,0) -> 0.14596795 | F16: =IFERROR(HistoricalFS!F36/HistoricalFS!F6,0) -> 0.15916346 | G16: =IFERROR(HistoricalFS!G36/HistoricalFS!G6,0) -> 0.16647529 | H16: =IFERROR(HistoricalFS!H36/HistoricalFS!H6,0) -> 0.16537009 | I16: =IFERROR(HistoricalFS!I36/HistoricalFS!I6,0) -> 0.16003632 | J16: =IFERROR(HistoricalFS!J36/HistoricalFS!J6,0) -> 0.1529178 | K16: =IFERROR(HistoricalFS!K36/HistoricalFS!K6,0) -> 0.14811236 | L16: =IFERROR(HistoricalFS!#REF!/HistoricalFS!#REF!,0) -> 0 | M16: =IFERROR(HistoricalFS!#REF!/HistoricalFS!#REF!,0) -> 0
A19: # | B19: Balance Sheet
B20: Equity Share Capital | C20: =IFERROR(HistoricalFS!C50/HistoricalFS!C$54,0) -> 0.013752706 | D20: =IFERROR(HistoricalFS!D50/HistoricalFS!D$54,0) -> 0.012092711 | E20: =IFERROR(HistoricalFS!E50/HistoricalFS!E$54,0) -> 0.011594825 | F20: =IFERROR(HistoricalFS!F50/HistoricalFS!F$54,0) -> 0.010718007 | G20: =IFERROR(HistoricalFS!G50/HistoricalFS!G$54,0) -> 0.0034186791 | H20: =IFERROR(HistoricalFS!H50/HistoricalFS!H$54,0) -> 0.0033330497 | I20: =IFERROR(HistoricalFS!I50/HistoricalFS!I$54,0) -> 0.0032157861 | J20: =IFERROR(HistoricalFS!J50/HistoricalFS!J$54,0) -> 0.0029940501 | K20: =IFERROR(HistoricalFS!K50/HistoricalFS!K$54,0) -> 0.0029425391 | L20: =IFERROR(HistoricalFS!#REF!/HistoricalFS!#REF!,0) -> 0
B21: Reserves | C21: =IFERROR(HistoricalFS!C51/HistoricalFS!C$54,0) -> 0.41563734 | D21: =IFERROR(HistoricalFS!D51/HistoricalFS!D$54,0) -> 0.39553242 | E21: =IFERROR(HistoricalFS!E51/HistoricalFS!E$54,0) -> 0.41070374 | F21: =IFERROR(HistoricalFS!F51/HistoricalFS!F$54,0) -> 0.3976083 | G21: =IFERROR(HistoricalFS!G51/HistoricalFS!G$54,0) -> 0.6901222 | H21: =IFERROR(HistoricalFS!H51/HistoricalFS!H$54,0) -> 0.69250844 | I21: =IFERROR(HistoricalFS!I51/HistoricalFS!I$54,0) -> 0.68515402 | J21: =IFERROR(HistoricalFS!J51/HistoricalFS!J$54,0) -> 0.64955599 | K21: =IFERROR(HistoricalFS!K51/HistoricalFS!K$54,0) -> 0.61564179 | L21: =IFERROR(HistoricalFS!#REF!/HistoricalFS!#REF!,0) -> 0
B22: Borrowings | C22: =IFERROR(HistoricalFS!C52/HistoricalFS!C$54,0) -> 0.017636572 | D22: =IFERROR(HistoricalFS!D52/HistoricalFS!D$54,0) -> 0 | E22: =IFERROR(HistoricalFS!E52/HistoricalFS!E$54,0) -> 0.0053142949 | F22: =IFERROR(HistoricalFS!F52/HistoricalFS!F$54,0) -> 0 | G22: =IFERROR(HistoricalFS!G52/HistoricalFS!G$54,0) -> 0 | H22: =IFERROR(HistoricalFS!H52/HistoricalFS!H$54,0) -> 0.014793067 | I22: =IFERROR(HistoricalFS!I52/HistoricalFS!I$54,0) -> 0.016681035 | J22: =IFERROR(HistoricalFS!J52/HistoricalFS!J$54,0) -> 0.018907108 | K22: =IFERROR(HistoricalFS!K52/HistoricalFS!K$54,0) -> 0.020635338 | L22: =IFERROR(HistoricalFS!#REF!/HistoricalFS!#REF!,0) -> 0
B23: Other Liabilities | C23: =IFERROR(HistoricalFS!C53/HistoricalFS!C$54,0) -> 0.55297339 | D23: =IFERROR(HistoricalFS!D53/HistoricalFS!D$54,0) -> 0.59237487 | E23: =IFERROR(HistoricalFS!E53/HistoricalFS!E$54,0) -> 0.57238714 | F23: =IFERROR(HistoricalFS!F53/HistoricalFS!F$54,0) -> 0.5916737 | G23: =IFERROR(HistoricalFS!G53/HistoricalFS!G$54,0) -> 0.30645912 | H23: =IFERROR(HistoricalFS!H53/HistoricalFS!H$54,0) -> 0.28936544 | I23: =IFERROR(HistoricalFS!I53/HistoricalFS!I$54,0) -> 0.29494916 | J23: =IFERROR(HistoricalFS!J53/HistoricalFS!J$54,0) -> 0.32854285 | K23: =IFERROR(HistoricalFS!K53/HistoricalFS!K$54,0) -> 0.36078034 | L23: =IFERROR(HistoricalFS!#REF!/HistoricalFS!#REF!,0) -> 0
B24: Total Liabilities | C24: =IFERROR(HistoricalFS!C54/HistoricalFS!C$54,0) -> 1 | D24: =IFERROR(HistoricalFS!D54/HistoricalFS!D$54,0) -> 1 | E24: =IFERROR(HistoricalFS!E54/HistoricalFS!E$54,0) -> 1 | F24: =IFERROR(HistoricalFS!F54/HistoricalFS!F$54,0) -> 1 | G24: =IFERROR(HistoricalFS!G54/HistoricalFS!G$54,0) -> 1 | H24: =IFERROR(HistoricalFS!H54/HistoricalFS!H$54,0) -> 1 | I24: =IFERROR(HistoricalFS!I54/HistoricalFS!I$54,0) -> 1 | J24: =IFERROR(HistoricalFS!J54/HistoricalFS!J$54,0) -> 1 | K24: =IFERROR(HistoricalFS!K54/HistoricalFS!K$54,0) -> 1 | L24: =IFERROR(HistoricalFS!#REF!/HistoricalFS!#REF!,0) -> 0
B26: Fixed Assets Net Block | C26: =IFERROR(HistoricalFS!C56/HistoricalFS!C$67,0) -> 0.28135744 | D26: =IFERROR(HistoricalFS!D56/HistoricalFS!D$67,0) -> 0.25349905 | E26: =IFERROR(HistoricalFS!E56/HistoricalFS!E$67,0) -> 0.25310001 | F26: =IFERROR(HistoricalFS!F56/HistoricalFS!F$67,0) -> 0.27187019 | G26: =IFERROR(HistoricalFS!G56/HistoricalFS!G$67,0) -> 0.74837067 | H26: =IFERROR(HistoricalFS!H56/HistoricalFS!H$67,0) -> 0.73005134 | I26: =IFERROR(HistoricalFS!I56/HistoricalFS!I$67,0) -> 0.72085608 | J26: =IFERROR(HistoricalFS!J56/HistoricalFS!J$67,0) -> 0.68473289 | K26: =IFERROR(HistoricalFS!K56/HistoricalFS!K$67,0) -> 0.6803526 | L26: =IFERROR(HistoricalFS!#REF!/HistoricalFS!#REF!,0) -> 0
B27: Capital Work in Progress | C27: =IFERROR(HistoricalFS!C57/HistoricalFS!C$67,0) -> 0.014580415 | D27: =IFERROR(HistoricalFS!D57/HistoricalFS!D$67,0) -> 0.02580898 | E27: =IFERROR(HistoricalFS!E57/HistoricalFS!E$67,0) -> 0.021793977 | F27: =IFERROR(HistoricalFS!F57/HistoricalFS!F$67,0) -> 0.029623381 | G27: =IFERROR(HistoricalFS!G57/HistoricalFS!G$67,0) -> 0.01083794 | H27: =IFERROR(HistoricalFS!H57/HistoricalFS!H$67,0) -> 0.018622529 | I27: =IFERROR(HistoricalFS!I57/HistoricalFS!I$67,0) -> 0.01549051 | J27: =IFERROR(HistoricalFS!J57/HistoricalFS!J$67,0) -> 0.013059155 | K27: =IFERROR(HistoricalFS!K57/HistoricalFS!K$67,0) -> 0.012634136 | L27: =IFERROR(HistoricalFS!#REF!/HistoricalFS!#REF!,0) -> 0
B28: Investments | C28: =IFERROR(HistoricalFS!C58/HistoricalFS!C$67,0) -> 0.24156373 | D28: =IFERROR(HistoricalFS!D58/HistoricalFS!D$67,0) -> 0.16084425 | E28: =IFERROR(HistoricalFS!E58/HistoricalFS!E$67,0) -> 0.14579419 | F28: =IFERROR(HistoricalFS!F58/HistoricalFS!F$67,0) -> 0.062273607 | G28: =IFERROR(HistoricalFS!G58/HistoricalFS!G$67,0) -> 0.039409369 | H28: =IFERROR(HistoricalFS!H58/HistoricalFS!H$67,0) -> 0.049939012 | I28: =IFERROR(HistoricalFS!I58/HistoricalFS!I$67,0) -> 0.039437853 | J28: =IFERROR(HistoricalFS!J58/HistoricalFS!J$67,0) -> 0.058925455 | K28: =IFERROR(HistoricalFS!K58/HistoricalFS!K$67,0) -> 0.047706698 | L28: =IFERROR(HistoricalFS!#REF!/HistoricalFS!#REF!,0) -> 0
B29: Other Assets | C29: =IFERROR(HistoricalFS!C59/HistoricalFS!C$67,0) -> 0.11524258 | D29: =IFERROR(HistoricalFS!D59/HistoricalFS!D$67,0) -> 0.15071101 | E29: =IFERROR(HistoricalFS!E59/HistoricalFS!E$67,0) -> 0.14198293 | F29: =IFERROR(HistoricalFS!F59/HistoricalFS!F$67,0) -> 0.18821019 | G29: =IFERROR(HistoricalFS!G59/HistoricalFS!G$67,0) -> 0.058699447 | H29: =IFERROR(HistoricalFS!H59/HistoricalFS!H$67,0) -> 0.057030607 | I29: =IFERROR(HistoricalFS!I59/HistoricalFS!I$67,0) -> 0.059895726 | J29: =IFERROR(HistoricalFS!J59/HistoricalFS!J$67,0) -> 0.057549466 | K29: =IFERROR(HistoricalFS!K59/HistoricalFS!K$67,0) -> 0.061618021 | L29: =IFERROR(HistoricalFS!#REF!/HistoricalFS!#REF!,0) -> 0
B30: Total Non-Current Assets | C30: =IFERROR(HistoricalFS!C60/HistoricalFS!C$67,0) -> 0.65274417 | D30: =IFERROR(HistoricalFS!D60/HistoricalFS!D$67,0) -> 0.59086329 | E30: =IFERROR(HistoricalFS!E60/HistoricalFS!E$67,0) -> 0.5626711 | F30: =IFERROR(HistoricalFS!F60/HistoricalFS!F$67,0) -> 0.55197737 | G30: =IFERROR(HistoricalFS!G60/HistoricalFS!G$67,0) -> 0.85731743 | H30: =IFERROR(HistoricalFS!H60/HistoricalFS!H$67,0) -> 0.85564349 | I30: =IFERROR(HistoricalFS!I60/HistoricalFS!I$67,0) -> 0.83568017 | J30: =IFERROR(HistoricalFS!J60/HistoricalFS!J$67,0) -> 0.81426697 | K30: =IFERROR(HistoricalFS!K60/HistoricalFS!K$67,0) -> 0.80231146 | L30: =IFERROR(HistoricalFS!#REF!/HistoricalFS!#REF!,0) -> 0
B32: Receivables | C32: =IFERROR(HistoricalFS!C62/HistoricalFS!C$67,0) -> 0.06908188 | D32: =IFERROR(HistoricalFS!D62/HistoricalFS!D$67,0) -> 0.073340052 | E32: =IFERROR(HistoricalFS!E62/HistoricalFS!E$67,0) -> 0.09748242 | F32: =IFERROR(HistoricalFS!F62/HistoricalFS!F$67,0) -> 0.057013844 | G32: =IFERROR(HistoricalFS!G62/HistoricalFS!G$67,0) -> 0.025574629 | H32: =IFERROR(HistoricalFS!H62/HistoricalFS!H$67,0) -> 0.031713613 | I32: =IFERROR(HistoricalFS!I62/HistoricalFS!I$67,0) -> 0.04213364 | J32: =IFERROR(HistoricalFS!J62/HistoricalFS!J$67,0) -> 0.038183695 | K32: =IFERROR(HistoricalFS!K62/HistoricalFS!K$67,0) -> 0.047819391 | L32: =IFERROR(HistoricalFS!#REF!/HistoricalFS!#REF!,0) -> 0
B33: Inventory | C33: =IFERROR(HistoricalFS!C63/HistoricalFS!C$67,0) -> 0.1617853 | D33: =IFERROR(HistoricalFS!D63/HistoricalFS!D$67,0) -> 0.14068973 | E33: =IFERROR(HistoricalFS!E63/HistoricalFS!E$67,0) -> 0.13817167 | F33: =IFERROR(HistoricalFS!F63/HistoricalFS!F$67,0) -> 0.13729966 | G33: =IFERROR(HistoricalFS!G63/HistoricalFS!G$67,0) -> 0.052065755 | H33: =IFERROR(HistoricalFS!H63/HistoricalFS!H$67,0) -> 0.058094347 | I33: =IFERROR(HistoricalFS!I63/HistoricalFS!I$67,0) -> 0.058171518 | J33: =IFERROR(HistoricalFS!J63/HistoricalFS!J$67,0) -> 0.051242849 | K33: =IFERROR(HistoricalFS!K63/HistoricalFS!K$67,0) -> 0.055282171 | L33: =IFERROR(HistoricalFS!#REF!/HistoricalFS!#REF!,0) -> 0
B34: Cash & Bank | C34: =IFERROR(HistoricalFS!C64/HistoricalFS!C$67,0) -> 0.11638864 | D34: =IFERROR(HistoricalFS!D64/HistoricalFS!D$67,0) -> 0.19510693 | E34: =IFERROR(HistoricalFS!E64/HistoricalFS!E$67,0) -> 0.20167481 | F34: =IFERROR(HistoricalFS!F64/HistoricalFS!F$67,0) -> 0.25370913 | G34: =IFERROR(HistoricalFS!G64/HistoricalFS!G$67,0) -> 0.065042188 | H34: =IFERROR(HistoricalFS!H64/HistoricalFS!H$67,0) -> 0.054548549 | I34: =IFERROR(HistoricalFS!I64/HistoricalFS!I$67,0) -> 0.064014669 | J34: =IFERROR(HistoricalFS!J64/HistoricalFS!J$67,0) -> 0.096306489 | K34: =IFERROR(HistoricalFS!K64/HistoricalFS!K$67,0) -> 0.09458698 | L34: =IFERROR(HistoricalFS!#REF!/HistoricalFS!#REF!,0) -> 0
B35: Total Current Assets | C35: =IFERROR(HistoricalFS!C65/HistoricalFS!C$67,0) -> 0.34725583 | D35: =IFERROR(HistoricalFS!D65/HistoricalFS!D$67,0) -> 0.40913671 | E35: =IFERROR(HistoricalFS!E65/HistoricalFS!E$67,0) -> 0.4373289 | F35: =IFERROR(HistoricalFS!F65/HistoricalFS!F$67,0) -> 0.44802263 | G35: =IFERROR(HistoricalFS!G65/HistoricalFS!G$67,0) -> 0.14268257 | H35: =IFERROR(HistoricalFS!H65/HistoricalFS!H$67,0) -> 0.14435651 | I35: =IFERROR(HistoricalFS!I65/HistoricalFS!I$67,0) -> 0.16431983 | J35: =IFERROR(HistoricalFS!J65/HistoricalFS!J$67,0) -> 0.18573303 | K35: =IFERROR(HistoricalFS!K65/HistoricalFS!K$67,0) -> 0.19768854 | L35: =IFERROR(HistoricalFS!#REF!/HistoricalFS!#REF!,0) -> 0
B37: Total Assets | C37: =IFERROR(HistoricalFS!C67/HistoricalFS!C$67,0) -> 1 | D37: =IFERROR(HistoricalFS!D67/HistoricalFS!D$67,0) -> 1 | E37: =IFERROR(HistoricalFS!E67/HistoricalFS!E$67,0) -> 1 | F37: =IFERROR(HistoricalFS!F67/HistoricalFS!F$67,0) -> 1 | G37: =IFERROR(HistoricalFS!G67/HistoricalFS!G$67,0) -> 1 | H37: =IFERROR(HistoricalFS!H67/HistoricalFS!H$67,0) -> 1 | I37: =IFERROR(HistoricalFS!I67/HistoricalFS!I$67,0) -> 1 | J37: =IFERROR(HistoricalFS!J67/HistoricalFS!J$67,0) -> 1 | K37: =IFERROR(HistoricalFS!K67/HistoricalFS!K$67,0) -> 1 | L37: =IFERROR(HistoricalFS!#REF!/HistoricalFS!#REF!,0) -> 0

Sheet Ratio Analysis
B2: ="Ratio Analysis - "&'Data Sheet'!B1 -> Ratio Analysis - HINDUSTAN UNILEVER LTD
B3: Years | C3: ='Data Sheet'!B16 -> 42825 | D3: ='Data Sheet'!C16 -> 43190 | E3: ='Data Sheet'!D16 -> 43555 | F3: ='Data Sheet'!E16 -> 43921 | G3: ='Data Sheet'!F16 -> 44286 | H3: ='Data Sheet'!G16 -> 44651 | I3: ='Data Sheet'!H16 -> 45016 | J3: ='Data Sheet'!I16 -> 45382 | K3: ='Data Sheet'!J16 -> 45747 | L3: ='Data Sheet'!#REF! -> #REF! | M3: Trends | N3: Mean | O3: Median
B5: SalesGrowth | C5: =IFERROR(HistoricalFS!C7,0) -> - | D5: =IFERROR(HistoricalFS!D7,0) -> 0.071859357 | E5: =IFERROR(HistoricalFS!E7,0) -> 0.10592207 | F5: =IFERROR(HistoricalFS!F7,0) -> 0.012032562 | G5: =IFERROR(HistoricalFS!G7,0) -> 0.18211296 | H5: =IFERROR(HistoricalFS!H7,0) -> 0.11520796 | I5: =IFERROR(HistoricalFS!I7,0) -> 0.15509286 | J5: =IFERROR(HistoricalFS!J7,0) -> 0.021723341 | K5: =IFERROR(HistoricalFS!K7,0) -> 0.019791263 | L5: =IFERROR(HistoricalFS!#REF!,0) -> 0 | N5: =IFERROR(AVERAGE(D5:L5),0) -> 0.075971375 | O5: =IFERROR(MEDIAN(D5:L5),0) -> 0.071859357
B6: EBITDA Growth | C6: - | D6: =IFERROR(HistoricalFS!D18/HistoricalFS!C18-1,0) -> 0.18505057 | E6: =IFERROR(HistoricalFS!E18/HistoricalFS!D18-1,0) -> 0.18415789 | F6: =IFERROR(HistoricalFS!F18/HistoricalFS!E18-1,0) -> 0.11047297 | G6: =IFERROR(HistoricalFS!G18/HistoricalFS!F18-1,0) -> 0.17898793 | H6: =IFERROR(HistoricalFS!H18/HistoricalFS!G18-1,0) -> 0.10588336 | I6: =IFERROR(HistoricalFS!I18/HistoricalFS!H18-1,0) -> 0.10033445 | J6: =IFERROR(HistoricalFS!J18/HistoricalFS!I18-1,0) -> 0.036191419 | K6: =IFERROR(HistoricalFS!K18/HistoricalFS!J18-1,0) -> 0.012552016 | L6: =IFERROR(HistoricalFS!#REF!/HistoricalFS!K18-1,0) -> 0 | N6: =IFERROR(AVERAGE(D6:L6),0) -> 0.10151451 | O6: =IFERROR(MEDIAN(D6:L6),0) -> 0.10588336
B7: EBIT Growth | C7: - | D7: =IFERROR((HistoricalFS!D30+HistoricalFS!D27)/(HistoricalFS!C30+HistoricalFS!C27)-1,0) -> 0.18368385 | E7: =IFERROR((HistoricalFS!E30-HistoricalFS!E27)/(HistoricalFS!D30-HistoricalFS!D27)-1,0) -> 0.19084741 | F7: =IFERROR((HistoricalFS!F30-HistoricalFS!F27)/(HistoricalFS!E30-HistoricalFS!E27)-1,0) -> 0.045338829 | G7: =IFERROR((HistoricalFS!G30-HistoricalFS!G27)/(HistoricalFS!F30-HistoricalFS!F27)-1,0) -> 0.19656732 | H7: =IFERROR((HistoricalFS!H30-HistoricalFS!H27)/(HistoricalFS!G30-HistoricalFS!G27)-1,0) -> 0.11979066 | I7: =IFERROR((HistoricalFS!I30-HistoricalFS!I27)/(HistoricalFS!H30-HistoricalFS!H27)-1,0) -> 0.10628354 | J7: =IFERROR((HistoricalFS!J30-HistoricalFS!J27)/(HistoricalFS!I30-HistoricalFS!I27)-1,0) -> -0.00054764513 | K7: =IFERROR((HistoricalFS!K30-HistoricalFS!K27)/(HistoricalFS!J30-HistoricalFS!J27)-1,0) -> -0.0060273973 | L7: =IFERROR((HistoricalFS!#REF!-HistoricalFS!#REF!)/(HistoricalFS!K30-HistoricalFS!K27)-1,0) -> 0 | N7: =IFERROR(AVERAGE(D7:L7),0) -> 0.09288184 | O7: =IFERROR(MEDIAN(D7:L7),0) -> 0.10628354
B8: NetProfitGrowth | C8: - | D8: =IFERROR(HistoricalFS!D36/HistoricalFS!C36-1,0) -> 0.25489186 | E8: =IFERROR(HistoricalFS!E36/HistoricalFS!D36-1,0) -> 0.17726713 | F8: =IFERROR(HistoricalFS!F36/HistoricalFS!E36-1,0) -> 0.10352039 | G8: =IFERROR(HistoricalFS!G36/HistoricalFS!F36-1,0) -> 0.23641819 | H8: =IFERROR(HistoricalFS!H36/HistoricalFS!G36-1,0) -> 0.10780432 | I8: =IFERROR(HistoricalFS!I36/HistoricalFS!H36-1,0) -> 0.11783697 | J8: =IFERROR(HistoricalFS!J36/HistoricalFS!I36-1,0) -> -0.023723569 | K8: =IFERROR(HistoricalFS!K36/HistoricalFS!J36-1,0) -> -0.012255679 | L8: =IFERROR(HistoricalFS!#REF!/HistoricalFS!K36-1,0) -> 0 | N8: =IFERROR(AVERAGE(D8:L8),0) -> 0.10686218 | O8: =IFERROR(MEDIAN(D8:L8),0) -> 0.10780432
B9: Dividend Growth | C9: - | D9: =IFERROR(HistoricalFS!D44/HistoricalFS!C44-1,0) -> 0.17636188 | E9: =IFERROR(HistoricalFS!E44/HistoricalFS!D44-1,0) -> 0.099898369 | F9: =IFERROR(HistoricalFS!F44/HistoricalFS!E44-1,0) -> 0.13631114 | G9: =IFERROR(HistoricalFS!G44/HistoricalFS!F44-1,0) -> 0.6238764 | H9: =IFERROR(HistoricalFS!H44/HistoricalFS!G44-1,0) -> -0.16049383 | I9: =IFERROR(HistoricalFS!I44/HistoricalFS!H44-1,0) -> 0.14705882 | J9: =IFERROR(HistoricalFS!J44/HistoricalFS!I44-1,0) -> 0.076923077 | K9: =IFERROR(HistoricalFS!K44/HistoricalFS!J44-1,0) -> 0.26190476 | L9: =IFERROR(HistoricalFS!#REF!/HistoricalFS!K44-1,0) -> 0 | N9: =IFERROR(AVERAGE(D9:L9),0) -> 0.15131563 | O9: =IFERROR(MEDIAN(D9:L9),0) -> 0.13631114
B11: Gross Margin | C11: =IFERROR(HistoricalFS!C13,0) -> 0.43685544 | D11: =IFERROR(HistoricalFS!D13,0) -> 0.45663244 | E11: =IFERROR(HistoricalFS!E13,0) -> 0.46372424 | F11: =IFERROR(HistoricalFS!F13,0) -> 0.48183898 | G11: =IFERROR(HistoricalFS!G13,0) -> 0.46200136 | H11: =IFERROR(HistoricalFS!H13,0) -> 0.44579186 | I11: =IFERROR(HistoricalFS!I13,0) -> 0.41596236 | J11: =IFERROR(HistoricalFS!J13,0) -> 0.45632997 | K11: =IFERROR(HistoricalFS!K13,0) -> 0.45297128 | L11: =IFERROR(HistoricalFS!#REF!,0) -> 0 | N11: =IFERROR(AVERAGE(C11:L11),0) -> 0.40721079 | O11: =IFERROR(MEDIAN(C11:L11),0) -> 0.45465063
B12: EBITDA Margin | C12: =IFERROR(HistoricalFS!C19,0) -> 0.19082082 | D12: =IFERROR(HistoricalFS!D19,0) -> 0.21097201 | E12: =IFERROR(HistoricalFS!E19,0) -> 0.22589672 | F12: =IFERROR(HistoricalFS!F19,0) -> 0.24786969 | G12: =IFERROR(HistoricalFS!G19,0) -> 0.24721443 | H12: =IFERROR(HistoricalFS!H19,0) -> 0.24514739 | I12: =IFERROR(HistoricalFS!I19,0) -> 0.23352592 | J12: =IFERROR(HistoricalFS!J19,0) -> 0.23683275 | K12: =IFERROR(HistoricalFS!K19,0) -> 0.23515153 | L12: =IFERROR(HistoricalFS!#REF!,0) -> 0 | N12: =IFERROR(AVERAGE(C12:L12),0) -> 0.20734313 | O12: =IFERROR(MEDIAN(C12:L12),0) -> 0.23433873
B13: EBIT Margin | C13: =IFERROR((HistoricalFS!C30+HistoricalFS!C27)/HistoricalFS!C6,0) -> 0.17779386 | D13: =IFERROR((HistoricalFS!D30+HistoricalFS!D27)/HistoricalFS!D6,0) -> 0.19634266 | E13: =IFERROR((HistoricalFS!E30+HistoricalFS!E27)/HistoricalFS!E6,0) -> 0.21152379 | F13: =IFERROR((HistoricalFS!F30+HistoricalFS!F27)/HistoricalFS!F6,0) -> 0.22268306 | G13: =IFERROR((HistoricalFS!G30+HistoricalFS!G27)/HistoricalFS!G6,0) -> 0.22437697 | H13: =IFERROR((HistoricalFS!H30+HistoricalFS!H27)/HistoricalFS!H6,0) -> 0.22434504 | I13: =IFERROR((HistoricalFS!I30+HistoricalFS!I27)/HistoricalFS!I6,0) -> 0.21475735 | J13: =IFERROR((HistoricalFS!J30+HistoricalFS!J27)/HistoricalFS!J6,0) -> 0.21718689 | K13: =IFERROR((HistoricalFS!K30+HistoricalFS!K27)/HistoricalFS!K6,0) -> 0.21368483 | L13: =IFERROR((HistoricalFS!#REF!+HistoricalFS!#REF!)/HistoricalFS!#REF!,0) -> 0 | N13: =IFERROR(AVERAGE(C13:L13),0) -> 0.19026944 | O13: =IFERROR(MEDIAN(C13:L13),0) -> 0.21422109
B14: EBT Margin | C14: =IFERROR(HistoricalFS!C31,0) -> 0.17673844 | D14: =IFERROR(HistoricalFS!D31,0) -> 0.1956112 | E14: =IFERROR(HistoricalFS!E31,0) -> 0.2106843 | F14: =IFERROR(HistoricalFS!F31,0) -> 0.21971696 | G14: =IFERROR(HistoricalFS!G31,0) -> 0.22188909 | H14: =IFERROR(HistoricalFS!H31,0) -> 0.22232391 | I14: =IFERROR(HistoricalFS!I31,0) -> 0.21287554 | J14: =IFERROR(HistoricalFS!J31,0) -> 0.21179075 | K14: =IFERROR(HistoricalFS!K31,0) -> 0.20742701 | L14: =IFERROR(HistoricalFS!#REF!,0) -> 0 | N14: =IFERROR(AVERAGE(C14:L14),0) -> 0.18790572 | O14: =IFERROR(MEDIAN(C14:L14),0) -> 0.21123753
B15: Net Profit Margin | C15: =IFERROR(HistoricalFS!C37,0) -> 0.11712201 | D15: =IFERROR(HistoricalFS!D37,0) -> 0.13712196 | E15: =IFERROR(HistoricalFS!E37,0) -> 0.14596795 | F15: =IFERROR(HistoricalFS!F37,0) -> 0.15916346 | G15: =IFERROR(HistoricalFS!G37,0) -> 0.16647529 | H15: =IFERROR(HistoricalFS!H37,0) -> 0.16537009 | I15: =IFERROR(HistoricalFS!I37,0) -> 0.16003632 | J15: =IFERROR(HistoricalFS!J37,0) -> 0.1529178 | K15: =IFERROR(HistoricalFS!K37,0) -> 0.14811236 | L15: =IFERROR(HistoricalFS!#REF!,0) -> 0 | N15: =IFERROR(AVERAGE(C15:L15),0) -> 0.13522872 | O15: =IFERROR(MEDIAN(C15:L15),0) -> 0.15051508
B17: SalesExpenses%Sales | C17: =IFERROR(HistoricalFS!C16,0) -> 0.43689424 | D17: =IFERROR(HistoricalFS!D16,0) -> 0.45210728 | E17: =IFERROR(HistoricalFS!E16,0) -> 0.44347991 | F17: =IFERROR(HistoricalFS!F16,0) -> 0.45153779 | G17: =IFERROR(HistoricalFS!G16,0) -> 0.39923323 | H17: =IFERROR(HistoricalFS!H16,0) -> 0.36203812 | I17: =IFERROR(HistoricalFS!I16,0) -> 0.31237105 | J17: =IFERROR(HistoricalFS!J16,0) -> 0.40373243 | K17: =IFERROR(HistoricalFS!K16,0) -> 0.39818703 | L17: =IFERROR(HistoricalFS!#REF!,0) -> 0 | N17: =IFERROR(AVERAGE(C17:L17),0) -> 0.36595811 | O17: =IFERROR(MEDIAN(C17:L17),0) -> 0.40148283
B18: Depreciation%Sales | C18: =IFERROR(HistoricalFS!C22,0) -> 0.013026959 | D18: =IFERROR(HistoricalFS!D22,0) -> 0.014629343 | E18: =IFERROR(HistoricalFS!E22,0) -> 0.014372933 | F18: =IFERROR(HistoricalFS!F22,0) -> 0.025186638 | G18: =IFERROR(HistoricalFS!G22,0) -> 0.022837459 | H18: =IFERROR(HistoricalFS!H22,0) -> 0.020802349 | I18: =IFERROR(HistoricalFS!I22,0) -> 0.01876857 | J18: =IFERROR(HistoricalFS!J22,0) -> 0.019645858 | K18: =IFERROR(HistoricalFS!K22,0) -> 0.021466707 | L18: =IFERROR(HistoricalFS!#REF!,0) -> 0 | N18: =IFERROR(AVERAGE(C18:L18),0) -> 0.017073681 | O18: =IFERROR(MEDIAN(C18:L18),0) -> 0.019207214
B19: OperatingIncome%Sales | C19: =C12 -> 0.19082082 | D19: =D12 -> 0.21097201 | E19: =E12 -> 0.22589672 | F19: =F12 -> 0.24786969 | G19: =G12 -> 0.24721443 | H19: =H12 -> 0.24514739 | I19: =I12 -> 0.23352592 | J19: =J12 -> 0.23683275 | ... L19: =L12 -> 0 | N19: =IFERROR(AVERAGE(C19:L19),0) -> 0.20734313 | O19: =IFERROR(MEDIAN(C19:L19),0) -> 0.23433873
B21: Return On Capital Employed | C21: =IFERROR((HistoricalFS!C30+HistoricalFS!C27)/(SUM(HistoricalFS!C50:C52)),0) -> 0.83976642 | D21: =IFERROR((HistoricalFS!D30+HistoricalFS!D27)/(SUM(HistoricalFS!D50:D52)),0) -> 0.95852218 | E21: =IFERROR((HistoricalFS!E30+HistoricalFS!E27)/(SUM(HistoricalFS!E50:E52)),0) -> 1.0438112 | F21: =IFERROR((HistoricalFS!F30+HistoricalFS!F27)/(SUM(HistoricalFS!F50:F52)),0) -> 1.0765585 | G21: =IFERROR((HistoricalFS!G30+HistoricalFS!G27)/(SUM(HistoricalFS!G50:G52)),0) -> 0.22133658 | H21: =IFERROR((HistoricalFS!H30+HistoricalFS!H27)/(SUM(HistoricalFS!H50:H52)),0) -> 0.23483155 | I21: =IFERROR((HistoricalFS!I30+HistoricalFS!I27)/(SUM(HistoricalFS!I50:I52)),0) -> 0.25250859 | J21: =IFERROR((HistoricalFS!J30+HistoricalFS!J27)/(SUM(HistoricalFS!J50:J52)),0) -> 0.25507571 | K21: =IFERROR((HistoricalFS!K30+HistoricalFS!K27)/(SUM(HistoricalFS!K50:K52)),0) -> 0.26421156 | L21: =IFERROR((HistoricalFS!#REF!+HistoricalFS!#REF!)/(SUM(HistoricalFS!#REF!)),0) -> 0 | N21: =IFERROR(AVERAGE(C21:L21),0) -> 0.51466223 | O21: =IFERROR(MEDIAN(C21:L21),0) -> 0.25964363
B22: Retained Earnings% | C22: =IFERROR(HistoricalFS!C47,0) -> 0.054582904 | D22: =IFERROR(HistoricalFS!D47,0) -> 0.11366434 | E22: =IFERROR(HistoricalFS!E47,0) -> 0.17183688 | F22: =IFERROR(HistoricalFS!F47,0) -> 0.14718888 | G22: =IFERROR(HistoricalFS!G47,0) -> 0 | H22: =IFERROR(HistoricalFS!H47,0) -> 0.078750144 | I22: =IFERROR(HistoricalFS!I47,0) -> 0.054667354 | J22: =IFERROR(HistoricalFS!J47,0) -> 0 | K22: =IFERROR(HistoricalFS!K47,0) -> 0 | L22: =IFERROR(HistoricalFS!#REF!,0) -> 0 | N22: =IFERROR(AVERAGE(C22:L22),0) -> 0.06206905 | O22: =IFERROR(MEDIAN(C22:L22),0) -> 0.054625129
B23: Return On Equity% | C23: =IFERROR(HistoricalFS!C36/(SUM(HistoricalFS!C50:C52)),0) -> 0.55319755 | D23: =IFERROR(HistoricalFS!D36/(SUM(HistoricalFS!D50:D52)),0) -> 0.66941354 | E23: =IFERROR(HistoricalFS!E36/(SUM(HistoricalFS!E50:E52)),0) -> 0.72031132 | F23: =IFERROR(HistoricalFS!F36/(SUM(HistoricalFS!F50:F52)),0) -> 0.76947381 | G23: =IFERROR(HistoricalFS!G36/(SUM(HistoricalFS!G50:G52)),0) -> 0.16421949 | H23: =IFERROR(HistoricalFS!H36/(SUM(HistoricalFS!H50:H52)),0) -> 0.17309995 | I23: =IFERROR(HistoricalFS!I36/(SUM(HistoricalFS!I50:I52)),0) -> 0.18816839 | J23: =IFERROR(HistoricalFS!J36/(SUM(HistoricalFS!J50:J52)),0) -> 0.1795947 | K23: =IFERROR(HistoricalFS!K36/(SUM(HistoricalFS!K50:K52)),0) -> 0.18313418 | L23: =IFERROR(HistoricalFS!#REF!/(SUM(HistoricalFS!#REF!)),0) -> 0 | N23: =IFERROR(AVERAGE(C23:L23),0) -> 0.36006129 | O23: =IFERROR(MEDIAN(C23:L23),0) -> 0.18565129
B24: Self Sustained Growth Rate | C24: =IFERROR(C22*C23,0) -> 0.030195129 | D24: =IFERROR(D22*D23,0) -> 0.076088449 | E24: =IFERROR(E22*E23,0) -> 0.12377605 | F24: =IFERROR(F22*F23,0) -> 0.11325799 | G24: =IFERROR(G22*G23,0) -> 0 | H24: =IFERROR(H22*H23,0) -> 0.013631646 | I24: =IFERROR(I22*I23,0) -> 0.010286668 | J24: =IFERROR(J22*J23,0) -> 0 | ... L24: =IFERROR(L22*L23,0) -> 0 | N24: =IFERROR(AVERAGE(C24:L24),0) -> 0.036723593 | O24: =IFERROR(MEDIAN(C24:L24),0) -> 0.011959157
B25: Interest Coverage Ratio | C25: =IFERROR((HistoricalFS!C30+HistoricalFS!C27)/HistoricalFS!C27,0) -> 168.45714 | D25: =IFERROR((HistoricalFS!D30+HistoricalFS!D27)/HistoricalFS!D27,0) -> 268.42308 | E25: =IFERROR((HistoricalFS!E30+HistoricalFS!E27)/HistoricalFS!E27,0) -> 251.9697 | F25: =IFERROR((HistoricalFS!F30+HistoricalFS!F27)/HistoricalFS!F27,0) -> 75.076271 | G25: =IFERROR((HistoricalFS!G30+HistoricalFS!G27)/HistoricalFS!G27,0) -> 90.188034 | H25: =IFERROR((HistoricalFS!H30+HistoricalFS!H27)/HistoricalFS!H27,0) -> 111 | I25: =IFERROR((HistoricalFS!I30+HistoricalFS!I27)/HistoricalFS!I27,0) -> 114.12281 | J25: =IFERROR((HistoricalFS!J30+HistoricalFS!J27)/HistoricalFS!J27,0) -> 40.248503 | K25: =IFERROR((HistoricalFS!K30+HistoricalFS!K27)/HistoricalFS!K27,0) -> 34.146835 | L25: =IFERROR((HistoricalFS!#REF!+HistoricalFS!#REF!)/HistoricalFS!#REF!,0) -> 0 | N25: =IFERROR(AVERAGE(C25:L25),0) -> 115.36324 | O25: =IFERROR(MEDIAN(C25:L25),0) -> 100.59402
B27: Debtor Turnover Ratio | C27: =IFERROR(HistoricalFS!C6/HistoricalFS!C62,0) -> 30.564055 | D27: =IFERROR(HistoricalFS!D6/HistoricalFS!D62,0) -> 27.133588 | E27: =IFERROR(HistoricalFS!E6/HistoricalFS!E62,0) -> 21.646476 | F27: =IFERROR(HistoricalFS!F6/HistoricalFS!F62,0) -> 34.624021 | G27: =IFERROR(HistoricalFS!G6/HistoricalFS!G62,0) -> 26.750853 | H27: =IFERROR(HistoricalFS!H6/HistoricalFS!H62,0) -> 23.455277 | I27: =IFERROR(HistoricalFS!I6/HistoricalFS!I62,0) -> 19.675219 | J27: =IFERROR(HistoricalFS!J6/HistoricalFS!J62,0) -> 20.652653 | K27: =IFERROR(HistoricalFS!K6/HistoricalFS!K62,0) -> 16.528149 | L27: =IFERROR(HistoricalFS!#REF!/HistoricalFS!#REF!,0) -> 0 | N27: =IFERROR(AVERAGE(C27:L27),0) -> 22.103029 | O27: =IFERROR(MEDIAN(C27:L27),0) -> 22.550877
B28: Creditor Turnover Ratio | C28: =IFERROR(HistoricalFS!C6/HistoricalFS!C53,0) -> 3.8183074 | D28: =IFERROR(HistoricalFS!D6/HistoricalFS!D53,0) -> 3.3593233 | E28: =IFERROR(HistoricalFS!E6/HistoricalFS!E53,0) -> 3.6865798 | F28: =IFERROR(HistoricalFS!F6/HistoricalFS!F53,0) -> 3.3363804 | G28: =IFERROR(HistoricalFS!G6/HistoricalFS!G53,0) -> 2.2324124 | H28: =IFERROR(HistoricalFS!H6/HistoricalFS!H53,0) -> 2.5706303 | I28: =IFERROR(HistoricalFS!I6/HistoricalFS!I53,0) -> 2.8106152 | J28: =IFERROR(HistoricalFS!J6/HistoricalFS!J53,0) -> 2.4002792 | K28: =IFERROR(HistoricalFS!K6/HistoricalFS!K53,0) -> 2.1907125 | L28: =IFERROR(HistoricalFS!#REF!/HistoricalFS!#REF!,0) -> 0 | N28: =IFERROR(AVERAGE(C28:L28),0) -> 2.6405241 | O28: =IFERROR(MEDIAN(C28:L28),0) -> 2.6906228
B29: Inventory Turnover | C29: =IFERROR(HistoricalFS!C6/HistoricalFS!C63,0) -> 13.050767 | D29: =IFERROR(HistoricalFS!D6/HistoricalFS!D63,0) -> 14.144449 | E29: =IFERROR(HistoricalFS!E6/HistoricalFS!E63,0) -> 15.27195 | F29: =IFERROR(HistoricalFS!F6/HistoricalFS!F63,0) -> 14.377665 | G29: =IFERROR(HistoricalFS!G6/HistoricalFS!G63,0) -> 13.139983 | H29: =IFERROR(HistoricalFS!H6/HistoricalFS!H63,0) -> 12.804199 | I29: =IFERROR(HistoricalFS!I6/HistoricalFS!I63,0) -> 14.250765 | J29: =IFERROR(HistoricalFS!J6/HistoricalFS!J63,0) -> 15.389359 | K29: =IFERROR(HistoricalFS!K6/HistoricalFS!K63,0) -> 14.296942 | L29: =IFERROR(HistoricalFS!#REF!/HistoricalFS!#REF!,0) -> 0 | N29: =IFERROR(AVERAGE(C29:L29),0) -> 12.672608 | O29: =IFERROR(MEDIAN(C29:L29),0) -> 14.197607
B30: Fixed Asset Turnover | C30: =IFERROR(HistoricalFS!C6/HistoricalFS!C56,0) -> 7.5044128 | E30: =IFERROR(HistoricalFS!E6/HistoricalFS!E56,0) -> 8.3372216 | F30: =IFERROR(HistoricalFS!F6/HistoricalFS!F56,0) -> 7.2609965 | G30: =IFERROR(HistoricalFS!G6/HistoricalFS!G56,0) -> 0.91417686 | H30: =IFERROR(HistoricalFS!H6/HistoricalFS!H56,0) -> 1.0189031 | I30: =IFERROR(HistoricalFS!I6/HistoricalFS!I56,0) -> 1.1500057 | J30: =IFERROR(HistoricalFS!J6/HistoricalFS!J56,0) -> 1.151682 | K30: =IFERROR(HistoricalFS!K6/HistoricalFS!K56,0) -> 1.1617006 | L30: =IFERROR(HistoricalFS!#REF!/HistoricalFS!#REF!,0) -> 0 | N30: =IFERROR(AVERAGE(C30:L30),0) -> 3.1665666 | O30: =IFERROR(MEDIAN(C30:L30),0) -> 1.151682
B31: Capital Turnover Ratio | C31: =IFERROR(HistoricalFS!C6/(SUM(HistoricalFS!C50:C51)),0) -> 4.9172598 | D31: =IFERROR(HistoricalFS!D6/(SUM(HistoricalFS!D50:D51)),0) -> 4.8818844 | E31: =IFERROR(HistoricalFS!E6/(SUM(HistoricalFS!E50:E51)),0) -> 4.9968222 | F31: =IFERROR(HistoricalFS!F6/(SUM(HistoricalFS!F50:F51)),0) -> 4.8344878 | G31: =IFERROR(HistoricalFS!G6/(SUM(HistoricalFS!G50:G51)),0) -> 0.98644964 | H31: =IFERROR(HistoricalFS!H6/(SUM(HistoricalFS!H50:H51)),0) -> 1.0689957 | I31: =IFERROR(HistoricalFS!I6/(SUM(HistoricalFS!I50:I51)),0) -> 1.204278 | J31: =IFERROR(HistoricalFS!J6/(SUM(HistoricalFS!J50:J51)),0) -> 1.2084814 | K31: =IFERROR(HistoricalFS!K6/(SUM(HistoricalFS!K50:K51)),0) -> 1.2777013 | L31: =IFERROR(HistoricalFS!#REF!/(SUM(HistoricalFS!#REF!)),0) -> 0 | N31: =IFERROR(AVERAGE(C31:L31),0) -> 2.537636 | O31: =IFERROR(MEDIAN(C31:L31),0) -> 1.2430914
B33: Debtor Days | C33: =IFERROR(365/C27,0) -> 11.942133 | D33: =IFERROR(365/D27,0) -> 13.451962 | E33: =IFERROR(365/E27,0) -> 16.861867 | F33: =IFERROR(365/F27,0) -> 10.541814 | G33: =IFERROR(365/G27,0) -> 13.644425 | H33: =IFERROR(365/H27,0) -> 15.56153 | I33: =IFERROR(365/I27,0) -> 18.551255 | J33: =IFERROR(365/J27,0) -> 17.673275 | ... L33: =IFERROR(365/L27,0) -> 0 | N33: =IFERROR(AVERAGE(C33:L33),0) -> 14.03118 | O33: =IFERROR(MEDIAN(C33:L33),0) -> 14.602977
B34: Payable Days | C34: =IFERROR(365/C28,0) -> 95.592093 | D34: =IFERROR(365/D28,0) -> 108.65283 | E34: =IFERROR(365/E28,0) -> 99.007759 | F34: =IFERROR(365/F28,0) -> 109.39999 | G34: =IFERROR(365/G28,0) -> 163.50026 | H34: =IFERROR(365/H28,0) -> 141.98852 | I34: =IFERROR(365/I28,0) -> 129.86481 | J34: =IFERROR(365/J28,0) -> 152.06564 | ... L34: =IFERROR(365/L28,0) -> 0 | N34: =IFERROR(AVERAGE(C34:L34),0) -> 116.66844 | O34: =IFERROR(MEDIAN(C34:L34),0) -> 119.6324
B35: Inventory Days | C35: =IFERROR(365/C29,0) -> 27.967704 | D35: =IFERROR(365/D29,0) -> 25.805177 | E35: =IFERROR(365/E29,0) -> 23.900025 | F35: =IFERROR(365/F29,0) -> 25.386597 | G35: =IFERROR(365/G29,0) -> 27.777813 | H35: =IFERROR(365/H29,0) -> 28.506273 | I35: =IFERROR(365/I29,0) -> 25.612661 | J35: =IFERROR(365/J29,0) -> 23.717688 | ... L35: =IFERROR(365/L29,0) -> 0 | N35: =IFERROR(AVERAGE(C35:L35),0) -> 23.420387 | O35: =IFERROR(MEDIAN(C35:L35),0) -> 25.571298
B36: Cash Conversion Cycle | C36: =SUM(C33,C35)-C34 -> -55.682257 | D36: =SUM(D33,D35)-D34 -> -69.395696 | E36: =SUM(E33,E35)-E34 -> -58.245866 | F36: =SUM(F33,F35)-F34 -> -73.471583 | G36: =SUM(G33,G35)-G34 -> -122.07802 | H36: =SUM(H33,H35)-H34 -> -97.920718 | I36: =SUM(I33,I35)-I34 -> -85.700891 | J36: =SUM(J33,J35)-J34 -> -110.67468 | ... L36: =SUM(L33,L35)-L34 -> 0 | N36: =IFERROR(AVERAGE(C36:L36),0) -> -79.21687 | O36: =IFERROR(MEDIAN(C36:L36),0) -> -79.586237
B38: CFO/Sales | C38: =IFERROR(HistoricalFS!C80/HistoricalFS!C6,0) -> 0.013750678 | D38: =IFERROR(HistoricalFS!D80/HistoricalFS!D6,0) -> 0.020509214 | E38: =IFERROR(HistoricalFS!E80/HistoricalFS!E6,0) -> 0.020503689 | F38: =IFERROR(HistoricalFS!F80/HistoricalFS!F6,0) -> 0.032199683 | G38: =IFERROR(HistoricalFS!G80/HistoricalFS!G6,0) -> 0.029237901 | H38: =IFERROR(HistoricalFS!H80/HistoricalFS!H6,0) -> 0.026179308 | I38: =IFERROR(HistoricalFS!I80/HistoricalFS!I6,0) -> 0.043413668 | J38: =IFERROR(HistoricalFS!J80/HistoricalFS!J6,0) -> 0.044348585 | K38: =IFERROR(HistoricalFS!K80/HistoricalFS!K6,0) -> 0.039020294 | L38: =IFERROR(HistoricalFS!#REF!/HistoricalFS!#REF!,0) -> 0 | N38: =IFERROR(AVERAGE(C38:L38),0) -> 0.026916302 | O38: =IFERROR(MEDIAN(C38:L38),0) -> 0.027708605
B39: CFO/Total Assets | C39: =IFERROR(HistoricalFS!C80/HistoricalFS!C67,0) -> 0.02903349 | D39: =IFERROR(HistoricalFS!D80/HistoricalFS!D67,0) -> 0.040812899 | E39: =IFERROR(HistoricalFS!E80/HistoricalFS!E67,0) -> 0.043265876 | F39: =IFERROR(HistoricalFS!F80/HistoricalFS!F67,0) -> 0.063563737 | G39: =IFERROR(HistoricalFS!G80/HistoricalFS!G67,0) -> 0.02000291 | H39: =IFERROR(HistoricalFS!H80/HistoricalFS!H67,0) -> 0.01947352 | I39: =IFERROR(HistoricalFS!I80/HistoricalFS!I67,0) -> 0.035989436 | J39: =IFERROR(HistoricalFS!J80/HistoricalFS!J67,0) -> 0.034973054 | K39: =IFERROR(HistoricalFS!K80/HistoricalFS!K67,0) -> 0.030840314 | L39: =IFERROR(HistoricalFS!#REF!/HistoricalFS!#REF!,0) -> 0 | N39: =IFERROR(AVERAGE(C39:L39),0) -> 0.031795524 | O39: =IFERROR(MEDIAN(C39:L39),0) -> 0.032906684
B40: CFO/Total Debt | C40: =IFERROR(HistoricalFS!C80/HistoricalFS!C52,0) -> 1.6462094 | D40: =IFERROR(HistoricalFS!D80/HistoricalFS!D52,0) -> 0 | E40: =IFERROR(HistoricalFS!E80/HistoricalFS!E52,0) -> 8.1414141 | F40: =IFERROR(HistoricalFS!F80/HistoricalFS!F52,0) -> 0 | G40: =IFERROR(HistoricalFS!G80/HistoricalFS!G52,0) -> 0 | H40: =IFERROR(HistoricalFS!H80/HistoricalFS!H52,0) -> 1.316395 | I40: =IFERROR(HistoricalFS!I80/HistoricalFS!I52,0) -> 2.1575062 | J40: =IFERROR(HistoricalFS!J80/HistoricalFS!J52,0) -> 1.8497305 | K40: =IFERROR(HistoricalFS!K80/HistoricalFS!K52,0) -> 1.4945388 | L40: =IFERROR(HistoricalFS!#REF!/HistoricalFS!#REF!,0) -> 0 | N40: =IFERROR(AVERAGE(C40:L40),0) -> 1.6605794 | O40: =IFERROR(MEDIAN(C40:L40),0) -> 1.4054669

Sheet Forecasting
B2: ='Data Sheet'!B1&" -"&" Sales Forecasting" -> HINDUSTAN UNILEVER LTD - Sales Forecasting | G2: ='Data Sheet'!B1&" -"&" EBITDA Forecasting" -> HINDUSTAN UNILEVER LTD - EBITDA Forecasting | L2: ='Data Sheet'!B1&" -"&" EBIT Forecasting" -> HINDUSTAN UNILEVER LTD - EBIT Forecasting | Q2: ='Data Sheet'!B1&" -"&" Depreciation Forecasting" -> HINDUSTAN UNILEVER LTD - Depreciation Forecasting
B3: Year Weight | C3: Year | D3: Sales | E3: Sales Growth | G3: Year Weight | H3: Year | I3: EBITDA | J3: EBITDA Growth | L3: Year Weight | M3: Year | N3: EBIT | O3: EBIT Growth | Q3: Year Weight | R3: Year | S3: D&A | T3: D&A as Sales% | U3: D&A Growth
B4: 1 | C4: {=TRANSPOSE('Data Sheet'!B16:J16)} -> 42825 | D4: {=TRANSPOSE('Data Sheet'!B17:J17)} -> 33162 | E4: - | G4: 1 | H4: 42825 | I4: {=TRANSPOSE(HistoricalFS!C18:K18)} -> 6328 | J4: - | L4: 1 | M4: 42825 | N4: {=TRANSPOSE(HistoricalFS!C24:K24)} -> 5896 | O4: - | Q4: 1 | R4: 42825 | S4: {=TRANSPOSE(HistoricalFS!C21:K21)} -> 432 | T4: {=TRANSPOSE(HistoricalFS!C22:K22)} -> 0.013026959 | U4: -
B5: 2 | C5: 43190 | D5: 35545 | E5: =(D5-D4)/D4 -> 0.071859357 | G5: 2 | H5: 43190 | I5: 7499 | J5: =(I5-I4)/I4 -> 0.18505057 | L5: 2 | M5: 43190 | N5: 6979 | O5: =(N5-N4)/N4 -> 0.18368385 | Q5: 2 | R5: 43190 | S5: 520 | T5: 0.014629343 | U5: =(S5-S4)/S4 -> 0.2037037
B6: 3 | C6: 43555 | D6: 39310 | E6: =(D6-D5)/D5 -> 0.10592207 | G6: 3 | H6: 43555 | I6: 8880 | J6: =(I6-I5)/I5 -> 0.18415789 | L6: 3 | M6: 43555 | N6: 8315 | O6: =(N6-N5)/N5 -> 0.19143144 | Q6: 3 | R6: 43555 | S6: 565 | T6: 0.014372933 | U6: =(S6-S5)/S5 -> 0.086538462
B7: 4 | C7: 43921 | D7: 39783 | E7: =(D7-D6)/D6 -> 0.012032562 | G7: 4 | H7: 43921 | I7: 9861 | J7: =(I7-I6)/I6 -> 0.11047297 | L7: 4 | M7: 43921 | N7: 8859 | O7: =(N7-N6)/N6 -> 0.065423933 | Q7: 4 | R7: 43921 | S7: 1002 | T7: 0.025186638 | U7: =(S7-S6)/S6 -> 0.77345133
B8: 5 | C8: 44286 | D8: 47028 | E8: =(D8-D7)/D7 -> 0.18211296 | G8: 5 | H8: 44286 | I8: 11626 | J8: =(I8-I7)/I7 -> 0.17898793 | L8: 5 | M8: 44286 | N8: 10552 | O8: =(N8-N7)/N7 -> 0.19110509 | Q8: 5 | R8: 44286 | S8: 1074 | T8: 0.022837459 | U8: =(S8-S7)/S7 -> 0.071856287
B9: 6 | C9: 44651 | D9: 52446 | E9: =(D9-D8)/D8 -> 0.11520796 | G9: 6 | H9: 44651 | I9: 12857 | J9: =(I9-I8)/I8 -> 0.10588336 | L9: 6 | M9: 44651 | N9: 11766 | O9: =(N9-N8)/N8 -> 0.11504928 | Q9: 6 | R9: 44651 | S9: 1091 | T9: 0.020802349 | U9: =(S9-S8)/S8 -> 0.015828678
B10: 7 | C10: 45016 | D10: 60580 | E10: =(D10-D9)/D9 -> 0.15509286 | G10: 7 | H10: 45016 | I10: 14147 | J10: =(I10-I9)/I9 -> 0.10033445 | L10: 7 | M10: 45016 | N10: 13010 | O10: =(N10-N9)/N9 -> 0.10572837 | Q10: 7 | R10: 45016 | S10: 1137 | T10: 0.01876857 | U10: =(S10-S9)/S9 -> 0.042163153
B11: 8 | C11: 45382 | D11: 61896 | E11: =(D11-D10)/D10 -> 0.021723341 | G11: 8 | H11: 45382 | I11: 14659 | J11: =(I11-I10)/I10 -> 0.036191419 | L11: 8 | M11: 45382 | N11: 13443 | O11: =(N11-N10)/N10 -> 0.033282091 | Q11: 8 | R11: 45382 | S11: 1216 | T11: 0.019645858 | U11: =(S11-S10)/S10 -> 0.069481091
B12: 9 | C12: 45747 | D12: 63121 | E12: =(D12-D11)/D11 -> 0.019791263 | G12: 9 | H12: 45747 | I12: 14843 | J12: =(I12-I11)/I11 -> 0.012552016 | L12: 9 | M12: 45747 | N12: 13488 | O12: =(N12-N11)/N11 -> 0.0033474671 | Q12: 9 | R12: 45747 | S12: 1355 | T12: 0.021466707 | U12: =(S12-S11)/S11 -> 0.11430921
B13: 10 | C13: 46082 | D13: =D12*(1+E13) -> 68170.68 | E13: 0.08 | G13: 10 | H13: 46082 | I13: =I12*(1+J13) -> 18331.105 | J13: 0.235 | L13: 10 | M13: 46082 | N13: =I13-S13 -> 16967.691 | O13: =(N13-N12)/N12 -> 0.25798424 | Q13: 10 | R13: 46082 | S13: =D13*T13 -> 1363.4136 | T13: 0.02 | U13: =(S13-S12)/S12 -> 0.0062092989
B14: 11 | C14: 46447 | D14: =D13*(1+E14) -> 74987.748 | E14: 0.1 | G14: 11 | H14: 46447 | I14: =I13*(1+J14) -> 22730.57 | J14: 0.24 | L14: 11 | M14: 46447 | N14: =I14-S14 -> 21230.815 | O14: =(N14-N13)/N13 -> 0.25124949 | Q14: 11 | R14: 46447 | S14: =D14*T14 -> 1499.755 | T14: 0.02 | U14: =(S14-S13)/S13 -> 0.1
B15: 12 | C15: 46813 | D15: =D14*(1+E15) -> 81736.645 | E15: 0.09 | G15: 12 | H15: 46813 | I15: =I14*(1+J15) -> 28185.907 | J15: 0.24 | L15: 12 | M15: 46813 | N15: =I15-S15 -> 26551.174 | O15: =(N15-N14)/N14 -> 0.25059607 | Q15: 12 | R15: 46813 | S15: =D15*T15 -> 1634.7329 | T15: 0.02 | U15: =(S15-S14)/S14 -> 0.09
B16: 13 | C16: 47178 | D16: =D15*(1+E16) -> 88275.577 | E16: 0.08 | G16: 13 | H16: 47178 | I16: =I15*(1+J16) -> 34809.595 | J16: 0.235 | L16: 13 | M16: 47178 | N16: =I16-S16 -> 33044.084 | O16: =(N16-N15)/N15 -> 0.24454322 | Q16: 13 | R16: 47178 | S16: =D16*T16 -> 1765.5115 | T16: 0.02 | U16: =(S16-S15)/S15 -> 0.08
B17: 14 | C17: 47543 | D17: =D16*(1+E17) -> 94454.867 | E17: 0.07 | G17: 14 | H17: 47543 | I17: =I16*(1+J17) -> 42989.85 | J17: 0.235 | L17: 14 | M17: 47543 | N17: =I17-S17 -> 41100.753 | O17: =(N17-N16)/N16 -> 0.24381578 | Q17: 14 | R17: 47543 | S17: =D17*T17 -> 1889.0973 | T17: 0.02 | U17: =(S17-S16)/S16 -> 0.07
B18: 15 | C18: 47908 | D18: =D17*(1+E18) -> 100122.16 | E18: 0.06 | G18: 15 | H18: 47908 | I18: =I17*(1+J18) -> 52877.516 | J18: 0.23 | L18: 15 | M18: 47908 | N18: =I18-S18 -> 50875.072 | O18: =(N18-N17)/N17 -> 0.23781364 | Q18: 15 | R18: 47908 | S18: =D18*T18 -> 2002.4432 | T18: 0.02 | U18: =(S18-S17)/S17 -> 0.06

Sheet DCF>
B1: Company | C1: Country | D1: Total Debt | E1: Total Equity | F1: Tax Rate
B2: Vishal Mega Mart | C2: India | D2: 1729 | E2: =4597+1804 -> 6401 | F2: 0.26
B3: V-Mart Retail | C3: India | D3: 783 | E3: 810 | F3: 0.26
B4: Shopper's Store | C4: India | D4: 3314 | E4: =55+266 -> 321 | F4: 0.26
B5: Electronics Mart | C5: India | D5: 1976 | E5: =385+1146 -> 1531 | F5: 0.26
B6: Patel Retail | C6: India | D6: 183 | E6: =25+110 -> 135 | F6: 0.26

Sheet DCF
B2: Calculation of PV of FCFF | E2: =HistoricalFS!K3 -> 45747 | F2: =E2+365 -> 46112 | G2: =F2+365 -> 46477 | H2: =G2+365 -> 46842 | I2: =H2+365 -> 47207 | J2: =I2+365 -> 47572
B4: Revenue | E4: =Forecasting!D12 -> 63121 | F4: =Forecasting!$D13 -> 68170.68 | G4: =Forecasting!$D14 -> 74987.748 | H4: =Forecasting!$D15 -> 81736.645 | I4: =Forecasting!$D16 -> 88275.577 | J4: =Forecasting!$D17 -> 94454.867
B5: EBITDA | E5: =Forecasting!I12 -> 14843 | F5: =Forecasting!I13 -> 18331.105 | G5: =Forecasting!I14 -> 22730.57 | H5: =Forecasting!I15 -> 28185.907 | I5: =Forecasting!I16 -> 34809.595 | J5: =Forecasting!I17 -> 42989.85
B6: EBIT | E6: =HistoricalFS!K24 -> 13488 | F6: =Forecasting!$N13 -> 16967.691 | G6: =Forecasting!$N14 -> 21230.815 | H6: =Forecasting!$N15 -> 26551.174 | I6: =Forecasting!$N16 -> 33044.084 | J6: =Forecasting!$N17 -> 41100.753
B7: Tax Rate | E7: =HistoricalFS!K33/HistoricalFS!K30 -> 0.28595433 | F7: 0.26 | G7: 0.26 | H7: 0.26 | I7: 0.26 | J7: 0.26
B8: EBIT (1-T) | E8: =E6*(1-E7) -> 9631.048 | F8: =F6*(1-F7) -> 12556.092 | G8: =G6*(1-G7) -> 15710.803 | H8: =H6*(1-H7) -> 19647.869 | I8: =I6*(1-I7) -> 24452.622 | J8: =J6*(1-J7) -> 30414.557
B9: Less : Reinvestment Rate | E9: 0.31830994 | F9: 0.31830994 | G9: 0.31830994 | H9: 0.31830994 | I9: 0.31830994 | J9: 0.31830994
